<?xml version="1.0" encoding="UTF-8"?>
<!-- Generated by org.testng.reporters.JUnitXMLReporter -->
<testsuite hostname="INBANGNBLENO10" name="Default test" tests="1" failures="1" timestamp="18 Oct 2018 09:15:10 GMT" time="61.156" errors="0">
  <testcase name="Test02ReceiveRetireThenPutawayAtSameLocation" time="35.937" classname="com.chkpoint.jaytest1.Inventory_Test_UnknownInvalid">
    <failure type="java.lang.AssertionError" message="Test01ReceiveRetireThenCycleCountAtSameLocation() &amp;lt;[Expected {Shipping Area=0, Receiving Area=0}]:[Actual {}]&amp;gt;">
      <![CDATA[java.lang.AssertionError: Test01ReceiveRetireThenCycleCountAtSameLocation() <[Expected {Shipping Area=0, Receiving Area=0}]:[Actual {}]>
	at org.testng.AssertJUnit.fail(AssertJUnit.java:59)
	at org.testng.AssertJUnit.assertTrue(AssertJUnit.java:24)
	at com.chkpoint.jaytest1.Inventory_Test_UnknownInvalid.verifyResults(Inventory_Test_UnknownInvalid.java:42)
	at com.chkpoint.jaytest1.Inventory_Test_UnknownInvalid.Test02ReceiveRetireThenPutawayAtSameLocation(Inventory_Test_UnknownInvalid.java:331)
	at sun.reflect.NativeMethodAccessorImpl.invoke0(Native Method)
	at sun.reflect.NativeMethodAccessorImpl.invoke(Unknown Source)
	at sun.reflect.DelegatingMethodAccessorImpl.invoke(Unknown Source)
	at java.lang.reflect.Method.invoke(Unknown Source)
	at org.testng.internal.MethodInvocationHelper.invokeMethod(MethodInvocationHelper.java:85)
	at org.testng.internal.Invoker.invokeMethod(Invoker.java:639)
	at org.testng.internal.Invoker.invokeTestMethod(Invoker.java:821)
	at org.testng.internal.Invoker.invokeTestMethods(Invoker.java:1131)
	at org.testng.internal.TestMethodWorker.invokeTestMethods(TestMethodWorker.java:124)
	at org.testng.internal.TestMethodWorker.run(TestMethodWorker.java:108)
	at org.testng.TestRunner.privateRun(TestRunner.java:773)
	at org.testng.TestRunner.run(TestRunner.java:623)
	at org.testng.SuiteRunner.runTest(SuiteRunner.java:357)
	at org.testng.SuiteRunner.runSequentially(SuiteRunner.java:352)
	at org.testng.SuiteRunner.privateRun(SuiteRunner.java:310)
	at org.testng.SuiteRunner.run(SuiteRunner.java:259)
	at org.testng.SuiteRunnerWorker.runSuite(SuiteRunnerWorker.java:52)
	at org.testng.SuiteRunnerWorker.run(SuiteRunnerWorker.java:86)
	at org.testng.TestNG.runSuitesSequentially(TestNG.java:1185)
	at org.testng.TestNG.runSuitesLocally(TestNG.java:1110)
	at org.testng.TestNG.run(TestNG.java:1018)
	at org.testng.remote.AbstractRemoteTestNG.run(AbstractRemoteTestNG.java:114)
	at org.testng.remote.RemoteTestNG.initAndRun(RemoteTestNG.java:251)
	at org.testng.remote.RemoteTestNG.main(RemoteTestNG.java:77)
]]>
    </failure>
  </testcase> <!-- Test02ReceiveRetireThenPutawayAtSameLocation -->
</testsuite> <!-- Default test -->
